{"uuid": "76987feb-3248-42af-9083-201ecfa79579", "children": ["6a5ab44b-d61f-4dd6-916d-7bd2d27738b2", "50a302bb-6715-4d4a-88ce-0047f4f44d56", "9fddcbe3-993a-446e-8174-1e4a04bdab62"], "befores": [{"name": "driver", "status": "broken", "statusDetails": {"message": "urllib3.exceptions.MaxRetryError: HTTPConnectionPool(host='127.0.0.1', port=4723): Max retries exceeded with url: /wd/hub/session (Caused by NewConnectionError('<urllib3.connection.HTTPConnection object at 0x00000201E64BEB38>: Failed to establish a new connection: [WinError 10061] 由于目标计算机积极拒绝，无法连接。',))\n", "trace": "  File \"D:\\python\\lib\\site-packages\\pluggy\\callers.py\", line 187, in _multicall\n    res = hook_impl.function(*args)\n  File \"D:\\python\\lib\\site-packages\\_pytest\\fixtures.py\", line 964, in pytest_fixture_setup\n    result = call_fixture_func(fixturefunc, request, kwargs)\n  File \"D:\\python\\lib\\site-packages\\_pytest\\fixtures.py\", line 788, in call_fixture_func\n    res = next(it)\n  File \"D:\\Users\\Administrator\\code\\PycharmProjects\\appium\\conftest.py\", line 11, in driver\n    driver = webdriver.Remote(command_executor, desired_caps)\n  File \"D:\\python\\lib\\site-packages\\appium\\webdriver\\webdriver.py\", line 151, in __init__\n    proxy\n  File \"D:\\python\\lib\\site-packages\\selenium\\webdriver\\remote\\webdriver.py\", line 157, in __init__\n    self.start_session(capabilities, browser_profile)\n  File \"D:\\python\\lib\\site-packages\\appium\\webdriver\\webdriver.py\", line 227, in start_session\n    response = self.execute(RemoteCommand.NEW_SESSION, parameters)\n  File \"D:\\python\\lib\\site-packages\\selenium\\webdriver\\remote\\webdriver.py\", line 319, in execute\n    response = self.command_executor.execute(driver_command, params)\n  File \"D:\\python\\lib\\site-packages\\selenium\\webdriver\\remote\\remote_connection.py\", line 374, in execute\n    return self._request(command_info[0], url, body=data)\n  File \"D:\\python\\lib\\site-packages\\selenium\\webdriver\\remote\\remote_connection.py\", line 397, in _request\n    resp = self._conn.request(method, url, body=body, headers=headers)\n  File \"D:\\python\\lib\\site-packages\\urllib3\\request.py\", line 80, in request\n    method, url, fields=fields, headers=headers, **urlopen_kw\n  File \"D:\\python\\lib\\site-packages\\urllib3\\request.py\", line 171, in request_encode_body\n    return self.urlopen(method, url, **extra_kw)\n  File \"D:\\python\\lib\\site-packages\\urllib3\\poolmanager.py\", line 330, in urlopen\n    response = conn.urlopen(method, u.request_uri, **kw)\n  File \"D:\\python\\lib\\site-packages\\urllib3\\connectionpool.py\", line 760, in urlopen\n    **response_kw\n  File \"D:\\python\\lib\\site-packages\\urllib3\\connectionpool.py\", line 760, in urlopen\n    **response_kw\n  File \"D:\\python\\lib\\site-packages\\urllib3\\connectionpool.py\", line 760, in urlopen\n    **response_kw\n  File \"D:\\python\\lib\\site-packages\\urllib3\\connectionpool.py\", line 720, in urlopen\n    method, url, error=e, _pool=self, _stacktrace=sys.exc_info()[2]\n  File \"D:\\python\\lib\\site-packages\\urllib3\\util\\retry.py\", line 436, in increment\n    raise MaxRetryError(_pool, url, error or ResponseError(cause))\n"}, "start": 1587211442141, "stop": 1587211447216}], "start": 1587211442141, "stop": 1587211448620}